Workbook

Sheet Inicio2
A1: InicioID | B1: InicioNombre | C1: IncioLogo
A2: ¡Hola!, debes inciar sesión | B2: App Visitador Médico | C2: Inicio2_Images/¡Hola!, debes inciar sesión.IncioLogo.022910.png

Sheet Principal
A1: PrincipalID | B1: PrincipalNombre | C1: PrincipalLogo | D1: PrincipalMensaje
A2: ¡Te damos la bienvenida a esta aplicación que te ayudara a tener los procesos referentes a la visita médica y el área comercial ordenados! | B2: App Visitador Médico | C2: Principal_Images/¡Te damos la bienvenida a esta apli_3999718207737642358.PrincipalLogo.png | D2: ¿Contamos contigo?

Sheet Farmacias
A1: ID_Farmacia | B1: Nombre | C1: RIF | D1: Dirección | E1: Ciudad | F1: Sector | G1: Estado | H1: ZonaID | I1: Teléfono | J1: ID_RepresentanteAsignado | K1: Teléfono Contacto | L1: Contacto | M1: Email | N1: Horario | O1: Productos Promocionados | P1: Producto_Interes | Q1: Segmentacion | R1: Potencial | S1: ContactoPrincipal | T1: CargoContacto | U1: Acción de Seguimiento | V1: Horario_Atención | W1: Instagram | X1: Última_Visita | Y1: Status | Z1: ID_Usuario | AA1: SUBMITTED BY
A2: 2 | B2: Farmacia Mas x Menos | C2: J-50449243-4 | D2: Automercado Más x Menos C.C. Maracay Plaza | E2: MCY | F2: Av. Bermudez Sur | G2: ARA | H2: 3 | I2: 0414-3434641 | J2: dispositivosbiofarco@gmail.com | K2: 0414-3434641 | L2: Dra. Angelica Pérez | Q2: Cadena | R2: Alto | U2: TRUE | X2: 45981.964 | Y2: Activa | Z2: repbiofarco | AA2: dispositivosbiofarco@gmail.com
A3: 3 | B3: Locatel Las Delicias | C3: J-50202212-0 | D3: La Floresta, Maracay | E3: MCY | F3: Las Delicias | G3: ARA | H3: 1 | J3: dispositivosbiofarco@gmail.com | K3: 0424-3388016 | L3: Dr. Vidal Ruiz | M3: farmaciallasdelicias@locatelve.com | Q3: Cadena | R3: Alto | U3: TRUE | X3: 45910 | Y3: Activa | Z3: repbiofarco | AA3: dispositivosbiofarco@gmail.com
A4: 5 | B4: Farma Shop Solidaria Ayacucho | C4: J-29773464-3 | D4: Av. Ayacucho, Maracay 2103, Aragua, Venezuela | E4: MCY | F4: El Centro | G4: ARA | H4: 5 | I4: 0412-9975205 | J4: dispositivosbiofarco@gmail.com | K4: 0412-1496651 | L4: Glenis López | Q4: Mini Cadena | R4: Medio | S4: Glenis López | T4: Encargada | U4: TRUE | W4: @farmashopgrupo | X4: 45981.903 | Y4: Activa | Z4: repbiofarco | AA4: dispositivosbiofarco@gmail.com
A5: 8 | B5: Farma Uno Plus | D5: Calle Los Jabillos con 106 local 105 Sector La Coromoto Maracay | E5: MCY | F5: La Coromoto | G5: ARA | H5: 5 | I5: 0424-3498998 | J5: dispositivosbiofarco@gmail.com | Q5: Independiente | R5: Bajo | U5: TRUE | W5: @farmaunoplus | X5: 45987.796 | Y5: Inactiva | Z5: repbiofarco | AA5: dispositivosbiofarco@gmail.com
A6: 12 | B6: Farmacia Brisas del Lago | D6: Brisas del Lago, Maracay | E6: MCY | F6: Brisas del Lago | G6: ARA | H6: 3 | J6: dispositivosbiofarco@gmail.com | Q6: Independiente | R6: Bajo | U6: TRUE | X6: 45987.796 | Y6: Inactiva | Z6: repbiofarco | AA6: dispositivosbiofarco@gmail.com
A7: 13 | B7: Farmacia Cajigal | C7: J-30791467-0 | D7: Los Olivos Nuevos, Maracay | E7: MCY | F7: Los Olivos Nuevos | G7: ARA | H7: 1 | J7: dispositivosbiofarco@gmail.com | K7: 0426-8338574 | M7: jsching4@gmail.com | Q7: Independiente | R7: Bajo | U7: TRUE | X7: 45933 | Y7: Activa | Z7: repbiofarco | AA7: dispositivosbiofarco@gmail.com
A8: 14 | B8: Farmacia Ciudad Jardín | C8: J-07548214-0 | D8: Av. Miranda, Maracay, Aragua, Venezuela | E8: MCY | F8: San Agustin | G8: ARA | H8: 2 | I8: 0243-2379965 | J8: dispositivosbiofarco@gmail.com | K8: 0243-2379965 | L8: Edith Guillen | M8: farmaciaciudadjardin@gmail.com | Q8: Independiente | R8: Bajo | S8: Edith Guillen | T8: Encargada | U8: TRUE | V8: Lun , Mar , Mie , Jue , Vie , Sab , Dom | X8: 45987.819 | Y8: Activa | Z8: repbiofarco | AA8: dispositivosbiofarco@gmail.com
A9: 16 | B9: Farmacia Farmadía | D9: El Piñonal, Maracay | E9: MCY | F9: El Piñonal | G9: ARA | H9: 4 | I9: 0414-0471853 | J9: dispositivosbiofarco@gmail.com | Q9: Mini Cadena | R9: Medio | U9: TRUE | X9: 45918 | Y9: Activa | Z9: repbiofarco | AA9: dispositivosbiofarco@gmail.com
A10: 17 | B10: Farmacia Gran Vía | C10: J-07509720-3 | D10: 70 Av. Miranda, Maracay 2101, Aragua, Venezuela | E10: MCY | F10: El Carmen | G10: ARA | H10: 2 | I10: 0243-2335512 | J10: dispositivosbiofarco@gmail.com | K10: 0414-1479994 | L10: Ana Matute | M10: farmaciagranviamcy@gmail.com | Q10: Independiente | R10: Bajo | U10: TRUE | X10: 45904 | Y10: Activa | Z10: repbiofarco | AA10: dispositivosbiofarco@gmail.com
A11: 19 | B11: Farmacia La Cooperativa del Norte | D11: La Cooperativa, Maracay | E11: MCY | F11: La Cooperativa | G11: ARA | H11: 1 | I11: 0243-2417887 | J11: dispositivosbiofarco@gmail.com | K11: 0414-4454909 | Q11: Independiente | R11: Bajo | U11: TRUE | W11: @lacooperativadelnorte | X11: 45930 | Y11: Activa | Z11: repbiofarco | AA11: dispositivosbiofarco@gmail.com
A12: 20 | B12: FARMACIAS EUROSALUD | D12: Local 5, Av miranda oeste, Maracay | E12: MCY | F12: La Romana | G12: ARA | I12: 0424-3105949 | J12: dispositivosbiofarco@gmail.com | Q12: Independiente | R12: Bajo | U12: TRUE | X12: 45930 | Y12: Inactiva | Z12: repbiofarco | AA12: dispositivosbiofarco@gmail.com
A13: 21 | B13: Farmacia Grupo VTF | C13: J-29660754-0 | D13: Av. Ayacucho esquina con calle Cajigal Número 45, Maracay | E13: MCY | F13: Av. Ayachucho | G13: ARA | H13: 5 | I13: 0412-9630293 | J13: dispositivosbiofarco@gmail.com | K13: 0412-8363029 | L13: Jesús Hidalgo | Q13: Independiente | R13: Bajo | U13: TRUE | X13: 45981.879 | Y13: Activa | Z13: repbiofarco | AA13: dispositivosbiofarco@gmail.com
A14: 22 | B14: Farmacia Lincoln | C14: J-30146726-4 | D14: Av. Bolívar, Maracay, Aragua, Venezuela | E14: MCY | F14: Centro | G14: ARA | H14: 2 | I14: 0414-5880833 | J14: dispositivosbiofarco@gmail.com | K14: 0412-398327 | L14: Rubexi Magallanes | Q14: Mini Cadena | R14: Medio | U14: TRUE | W14: @farmacialincoln | X14: 45981.851 | Y14: Activa | Z14: repbiofarco | AA14: dispositivosbiofarco@gmail.com
A15: 25 | B15: Farmacia Orinoco | C15: J-07548164-0 | D15: Av. principal de San José, Frente al IVSS, Maracay | E15: MCY | F15: San Jose | G15: ARA | H15: 4 | I15: 0412-4929888 | J15: dispositivosbiofarco@gmail.com | Q15: Independiente | R15: Bajo | U15: TRUE | W15: @farmaciaorinoco_mcy | X15: 45987.81 | Y15: Inactiva | Z15: repbiofarco | AA15: dispositivosbiofarco@gmail.com
A16: 26 | B16: Farmacia María de Jesús | D16: Avenida Constitución Centro comercial Colonial local B7, Santa Ana, Maracay | E16: MCY | F16: Santa Ana | G16: ARA | I16: 0424-3576470 | J16: dispositivosbiofarco@gmail.com | Q16: Independiente | R16: Bajo | U16: TRUE | W16: @farmaciamariadejesus0411 | X16: 45930 | Y16: Inactiva | Z16: repbiofarco | AA16: dispositivosbiofarco@gmail.com
A17: 28 | B17: Farmacia Paseo Las Delicias | C17: J-30377598-5 | D17: Las Delicias, Maracay | E17: MCY | F17: Las Delicias | G17: ARA | H17: 1 | I17: 0424-3005978 | J17: dispositivosbiofarco@gmail.com | K17: 0424-3005978 | L17: Mariela Gómez | Q17: Independiente | R17: Bajo | S17: Mariela Gómez | T17: Encargada | U17: TRUE | X17: 45981.962 | Y17: Activa | Z17: repbiofarco | AA17: dispositivosbiofarco@gmail.com
A18: 29 | B18: Farmacia Punto Blanco | C18: J-29334494-2 | D18: Centro comercial residencial White Point PB, Av. Fuerzas Aéreas, Parque Aragua, Maracay | E18: MCY | F18: Parque Aragua | G18: ARA | H18: 2 | I18: 0424-3202632 | J18: dispositivosbiofarco@gmail.com | Q18: Independiente | R18: Bajo | U18: TRUE | W18: @farmaciapuntoblancoca | X18: 45981.845 | Y18: Activa | Z18: repbiofarco | AA18: dispositivosbiofarco@gmail.com
A19: 32 | B19: Farmacia Rio Blanco | C19: J-07518491-2 | D19: Rio Blanco, Sector San Pedro Alejandro, Maracay | E19: STR | F19: Rio Blanco | G19: ARA | H19: 3 | I19: 0424-3370967 | J19: dispositivosbiofarco@gmail.com | K19: 0424-3370967 | L19: Mirla | Q19: Independiente | R19: Bajo | S19: Mirla | T19: Encargada | U19: TRUE | X19: 45981.798 | Y19: Activa | Z19: repbiofarco | AA19: dispositivosbiofarco@gmail.com
A20: 33 | B20: Farmacia Samán de Güere | C20: J-30285453-4 | D20: Sector, Intercomunal Maracay, Turmero, Maracay | E20: TUR | F20: Intercomunal | G20: ARA | H20: 4 | I20: 0412-9302356 | J20: dispositivosbiofarco@gmail.com | K20: 0412-9302356 | L20: José Navas | Q20: Mini Cadena | R20: Medio | U20: TRUE | V20: Lun , Mar , Mie , Jue , Vie , Sab , Dom | W20: @farmaciacentralturmero | X20: 45981.77 | Y20: Activa | Z20: repbiofarco | AA20: dispositivosbiofarco@gmail.com
A21: 36 | B21: Farmacia San Juan de Dios | D21: Barrio la Democracia, Calle Boyaca, Maracay | E21: MCY | F21: Barrio la Democracia | G21: ARA | I21: 0412-4410320 | J21: dispositivosbiofarco@gmail.com | Q21: Independiente | U21: TRUE | X21: 45987.811 | Y21: Inactiva | Z21: repbiofarco | AA21: dispositivosbiofarco@gmail.com
A22: 37 | B22: Farmacias Nuevo Siglo y Santo Remedio | C22: J-30927929-0 | D22: Edificio Mariño, Calle Rivas Con, Locales C, D Y E C. Sucre, Turmero | E22: TUR | F22: Turmero | G22: ARA | I22: 0244-6618043 | J22: dispositivosbiofarco@gmail.com | Q22: Cadena | R22: Alto | U22: TRUE | W22: @farmaciasnuevosiglo | X22: 45953 | Y22: Activa | Z22: repbiofarco | AA22: dispositivosbiofarco@gmail.com
A23: 46 | B23: Farmatodo Zuly | C23: J-00020200-1 | D23: Las Delicias 2101, Aragua, Venezuela | E23: MCY | F23: Las Delicias | G23: ARA | I23: 0243-2424540 | J23: dispositivosbiofarco@gmail.com | K23: 0416-3454987 | L23: Dra. Rosangela Montenegro | Q23: Cadena | U23: TRUE | X23: 45909 | Y23: Activa | Z23: repbiofarco | AA23: dispositivosbiofarco@gmail.com
A24: 47 | B24: Farmayor Av. Miranda | C24: J-41262894-4 | D24: Calle Páez entre calle Soublette y Boulevard Pérez Almarza, Maracay | E24: MCY | F24: Centro | G24: ARA | I24: 0243-2455689 | J24: dispositivosbiofarco@gmail.com | K24: 0414-4606599 | L24: Yamaris Rodríguez | M24: farmaciayalimentosfarmayor@gmail.com | Q24: Mini Cadena | U24: TRUE | X24: 45981.912 | Y24: Activa | Z24: repbiofarco | AA24: dispositivosbiofarco@gmail.com
A25: 48 | B25: Farmacia LaFarma C.C. Las Américas | C25: J-31116593-2 | D25: Avenida Las Delicias, Maracay 2101, Aragua, Venezuela | E25: MCY | F25: Las Delicias | G25: ARA | I25: 0412-4660774 | J25: dispositivosbiofarco@gmail.com | K25: 0412-4660774 | L25: Alejandra Franco | Q25: Mini Cadena | U25: TRUE | W25: @lafarmacclasamericas | X25: 45806 | Y25: Activa | Z25: repbiofarco | AA25: dispositivosbiofarco@gmail.com
A26: 50 | B26: Farmacia SAAS Av. Los Aviadores | C26: J-50265214-0 | D26: Av. Los Aviadores, Palo Negro, Maracay, Edo. Aragua. | E26: PLN | F26: Av. Los Aviadores | G26: ARA | I26: 0424-3080504 | J26: dispositivosbiofarco@gmail.com | K26: 0424-3774424 | L26: Briscarlet Romero | Q26: Cadena | U26: TRUE | W26: @farmaciasaas_aviadores | X26: 45922 | Y26: Activa | Z26: repbiofarco | AA26: dispositivosbiofarco@gmail.com
A27: 51 | B27: Farmacia El Sol II | C27: J-3083246-5 | D27: Local 1, C.C Hormiga Center, Av Bolivar, Nivel 1 Calle Sanchez Carrero, Maracay 2101, Aragua | E27: MCY | F27: Centro | G27: ARA | I27: 0412-1443505 | J27: dispositivosbiofarco@gmail.com | K27: 0412-1443505 | L27: Geisy | Q27: Mini Cadena | U27: TRUE | X27: 45981.92 | Y27: Activa | Z27: repbiofarco | AA27: dispositivosbiofarco@gmail.com
A28: 52 | B28: Farmacia El Sol | C28: J-00132395-3 | D28: Local #58, Av Miranda, 2101 Calle Sanchez Carrero, Maracay 2101, Aragua | E28: MCY | F28: Av Miranda | G28: ARA | H28: 2 | I28: 0424-3612060 | J28: dispositivosbiofarco@gmail.com | K28: 0412-4304678 | L28: Elizabeth Duran | Q28: Mini Cadena | R28: Medio | U28: TRUE | X28: 45902 | Y28: Activa | Z28: repbiofarco | AA28: dispositivosbiofarco@gmail.com
A29: 53 | B29: Farmacia SAAS Las Delicias | C29: J-07000750-8 | D29: 8C6Q+PXF, Av Principal El Castaño, Maracay 2101, Aragua, Venezuela | E29: MCY | F29: Delicias | G29: ARA | I29: 0424-3823338 | J29: dispositivosbiofarco@gmail.com | K29: 0424-3053065 | L29: Dulce García | Q29: Cadena | U29: TRUE | V29: Lun , Mar , Mie , Jue , Vie , Sab , Dom | W29: @saasav.lasdelicias | X29: 45917 | Y29: Activa | Z29: repbiofarco | AA29: dispositivosbiofarco@gmail.com
A30: 54 | B30: Farma Vital I | C30: J-2952214-9 | D30: Avenida Universidad, El Limón, Aragua, Venezuela | E30: MCY | F30: El Limón | G30: ARA | I30: 0414-0531788 | J30: dispositivosbiofarco@gmail.com | K30: 0412-4427134 | L30: Jenxy | Q30: Mini Cadena | U30: TRUE | X30: 45909 | Y30: Activa | Z30: repbiofarco | AA30: dispositivosbiofarco@gmail.com
A31: 55 | B31: Farma Vital Terminal Central | C31: J-07521484-6 | D31: Terminal de Pasajeros | E31: MCY | F31: Terminal | G31: ARA | I31: 0414-4751430 | J31: dispositivosbiofarco@gmail.com | K31: 0412-4170868 | L31: Betsamar | Q31: Mini Cadena | R31: Medio | U31: TRUE | X31: 45981.897 | Y31: Activa | Z31: repbiofarco | AA31: dispositivosbiofarco@gmail.com
A32: 56 | B32: Farma Vital, C. A | C32: J-29396399-0 | D32: Diagonal Clinica Lugo, C.C Vista Lago, Avenida 19 de Abril, Maracay 2101, Aragua | E32: MCY | F32: 19 de Abril | G32: ARA | H32: 2 | I32: 0412-8948596 | J32: dispositivosbiofarco@gmail.com | K32: 0424-3533959 | L32: Dilimary | M32: farmavitalmaracay@gmail.com | Q32: Mini Cadena | R32: Alto | U32: TRUE | X32: 45905 | Y32: Activa | Z32: repbiofarco | AA32: dispositivosbiofarco@gmail.com
A33: 57 | B33: Farma Vital Campo Alegre | C33: J-31072776-7 | D33: Av. Bermudez, Maracay 2103, Aragua, Venezuela | E33: MCY | F33: Sur de Aragua | G33: ARA | I33: 0412-4837874 | J33: dispositivosbiofarco@gmail.com | K33: 0424-3074961 | L33: Kariana Alfonso | Q33: Mini Cadena | U33: TRUE | X33: 45782 | Y33: Activa | Z33: repbiofarco | AA33: dispositivosbiofarco@gmail.com
A34: 65 | B34: Distufar Av. Bermudez | C34: J-50125197-5 | D34: Av. Bermudez, Maracay 2103, Aragua, Venezuela | E34: MCY | F34: Av. Bermudez Sur | G34: ARA | I34: 0412-8956128 | J34: dispositivosbiofarco@gmail.com | K34: 0412-5979880 | L34: Andrea Gutierrez | Q34: Mini Cadena | R34: Bajo | U34: TRUE | V34: Lun , Mar , Mie , Jue , Vie , Sab , Dom | X34: 45981.758 | Y34: Activa | Z34: repbiofarco | AA34: dispositivosbiofarco@gmail.com
A35: 66 | B35: Distufar Santa Ines | D35: Santa Ines, Maracay 2106, Aragua, Venezuela | E35: STR | F35: Santa Ines | G35: ARA | H35: 4 | I35: 0412-3982006 | J35: dispositivosbiofarco@gmail.com | K35: 0412-3982006 | L35: Yasmin | Q35: Mini Cadena | R35: Medio | U35: TRUE | X35: 45929 | Y35: Activa | Z35: repbiofarco | AA35: dispositivosbiofarco@gmail.com
A36: 67 | B36: Farmacia La Ganadera | C36: J-4028240-9 | D36: Av. Constitución, Maracay, Aragua, Venezuela | E36: MCY | F36: Santa Rosa | G36: ARA | I36: 0414-1518972 | J36: dispositivosbiofarco@gmail.com | K36: 0414-5340201 | L36: Jose Torres | Q36: Mini Cadena | U36: TRUE | W36: @farmacia_la_ganadera | X36: 45919 | Y36: Activa | Z36: repbiofarco | AA36: dispositivosbiofarco@gmail.com
A37: 69 | B37: Farma Milán Santa Rita | C37: J-50220672-8 | D37: Santa Rita, Aragua, Venezuela | E37: STR | F37: Santa Rita | G37: ARA | I37: 0414-9479464 | J37: dispositivosbiofarco@gmail.com | K37: 0412-7118891 | L37: Deisy Zar | M37: farmamilansantarita@gmail.com | Q37: Mini Cadena | U37: TRUE | X37: 45922 | Y37: Activa | Z37: repbiofarco | AA37: dispositivosbiofarco@gmail.com
A38: 70 | B38: Farma Milán La Morita | E38: STR | F38: La Morita | G38: ARA | I38: 0414-4636195 | J38: dispositivosbiofarco@gmail.com | K38: 0414-4636195 | L38: Fatima Fernandez | Q38: Mini Cadena | R38: Medio | U38: TRUE | X38: 45922 | Y38: Activa | Z38: repbiofarco | AA38: dispositivosbiofarco@gmail.com
A39: 71 | B39: Farmacia Farma Store | E39: MCY | F39: La Cooperativa | G39: ARA | I39: 0414-4907867 | J39: dispositivosbiofarco@gmail.com | K39: 0414-4907867 | L39: Veronica Olmos | Q39: Mini Cadena | U39: TRUE | X39: 45912 | Y39: Activa | Z39: repbiofarco | AA39: dispositivosbiofarco@gmail.com
A40: 72 | B40: Farmacia Policlinico Turmero | C40: J-31252864-3 | E40: TUR | F40: Turmero | G40: ARA | I40: 0244-6636742 | J40: dispositivosbiofarco@gmail.com | K40: 0424-3680773 | L40: Carolina Rodríguez | M40: farmaciapoliclinicoturmero@hotmail.com | Q40: Independiente | U40: TRUE | X40: 45981.861 | Y40: Activa | Z40: repbiofarco | AA40: dispositivosbiofarco@gmail.com
...

Sheet ContactosClave
A1: ID_Contacto | B1: ID_Farmacia | C1: NombreContacto | D1: RolEnFarmacia | E1: Telefono | F1: Email | G1: ID_Usuario | H1: SUBMITTED BY
G2: repbiofarco | H2: dispositivosbiofarco@gmail.com
A3: 2 | B3: 2 | C3: Dra. Angelica Pérez | E3: 0414-3434641 | G3: repbiofarco | H3: dispositivosbiofarco@gmail.com
A4: 3 | B4: 3 | C4: Dr. Vidal Ruiz | E4: 0424-3388016 | F4: farmaciallasdelicias@locatelve.com | G4: repbiofarco | H4: dispositivosbiofarco@gmail.com
G5: repbiofarco | H5: dispositivosbiofarco@gmail.com
A6: 5 | B6: 5 | E6: 0412-9975205 | G6: repbiofarco | H6: dispositivosbiofarco@gmail.com
G7: repbiofarco | H7: dispositivosbiofarco@gmail.com
G8: repbiofarco | H8: dispositivosbiofarco@gmail.com
A9: 8 | B9: 8 | G9: repbiofarco | H9: dispositivosbiofarco@gmail.com
G10: repbiofarco | H10: dispositivosbiofarco@gmail.com
G11: repbiofarco | H11: dispositivosbiofarco@gmail.com
G12: repbiofarco | H12: dispositivosbiofarco@gmail.com
A13: 12 | B13: 12 | G13: repbiofarco | H13: dispositivosbiofarco@gmail.com
A14: 13 | B14: 13 | G14: repbiofarco | H14: dispositivosbiofarco@gmail.com
A15: 14 | B15: 14 | G15: repbiofarco | H15: dispositivosbiofarco@gmail.com
G16: repbiofarco | H16: dispositivosbiofarco@gmail.com
A17: 16 | B17: 16 | G17: repbiofarco | H17: dispositivosbiofarco@gmail.com
A18: 17 | B18: 17 | C18: Ana Matute | E18: 0414-1479994 | F18: farmaciagranviamcy@gmail.com | G18: repbiofarco | H18: dispositivosbiofarco@gmail.com
G19: repbiofarco | H19: dispositivosbiofarco@gmail.com
A20: 19 | B20: 19 | E20: 0414-4454909 | G20: repbiofarco | H20: dispositivosbiofarco@gmail.com
A21: 20 | B21: 20 | G21: repbiofarco | H21: dispositivosbiofarco@gmail.com
A22: 21 | B22: 21 | G22: repbiofarco | H22: dispositivosbiofarco@gmail.com
A23: 22 | B23: 22 | C23: Rubexi Magallanes | E23: 0412-398327 | G23: repbiofarco | H23: dispositivosbiofarco@gmail.com
G24: repbiofarco | H24: dispositivosbiofarco@gmail.com
G25: repbiofarco | H25: dispositivosbiofarco@gmail.com
A26: 25 | B26: 25 | G26: repbiofarco | H26: dispositivosbiofarco@gmail.com
A27: 26 | B27: 26 | G27: repbiofarco | H27: dispositivosbiofarco@gmail.com
G28: repbiofarco | H28: dispositivosbiofarco@gmail.com
A29: 28 | B29: 28 | G29: repbiofarco | H29: dispositivosbiofarco@gmail.com
A30: 29 | B30: 29 | G30: repbiofarco | H30: dispositivosbiofarco@gmail.com
G31: repbiofarco | H31: dispositivosbiofarco@gmail.com
G32: repbiofarco | H32: dispositivosbiofarco@gmail.com
A33: 32 | B33: 32 | G33: repbiofarco | H33: dispositivosbiofarco@gmail.com
A34: 33 | B34: 33 | G34: repbiofarco | H34: dispositivosbiofarco@gmail.com
G35: repbiofarco | H35: dispositivosbiofarco@gmail.com
G36: repbiofarco | H36: dispositivosbiofarco@gmail.com
A37: 36 | B37: 36 | G37: repbiofarco | H37: dispositivosbiofarco@gmail.com
A38: 37 | B38: 37 | G38: repbiofarco | H38: dispositivosbiofarco@gmail.com
G39: repbiofarco | H39: dispositivosbiofarco@gmail.com
G40: repbiofarco | H40: dispositivosbiofarco@gmail.com
...

Sheet Fichero Farmacias
A1: ID_Farmacia | B1: Nombre | C1: RIF | D1: Ciudad | E1: Estado | F1: Productos Promocionados | G1: Dirección | H1: Sector | I1: Teléfono | J1: Teléfono Contacto | K1: Contacto | L1: Email | M1: Horario | N1: Producto_Interes | O1: Acción de Seguimiento | P1: Producto Existente | Q1: Cantidad | R1: Drogueria | S1: Prioridad | T1: Horario_Atención | U1: Instagram | V1: Última_Visita | W1: ID_Usuario | X1: SUBMITTED BY
A2: 1 | B2: Farmacia Mas x Menos | C2: 0414-3434641 | D2: Maracay | E2: Aragua | F2: Limonada Laxante , Zincosol , Fleryfol , NeuroVital Kids , Acetafen , Calzinc D , Vitacon C | G2: Automercado Más x Menos C.C. Maracay Plaza | H2: Av. Bermudez Sur | I2: 0414-3434641 | J2: 0414-3434641 | K2: Dra. Angelica Pérez | O2: Visitar para coodinar con la Dra. Angelica Perez regente de la farmacia | Q2: 1 | S2: Media | T2: 0.54166667 | V2: 45779 | W2: repbiofarco | X2: dispositivosbiofarco@gmail.com
A3: 2 | B3: Locatel Las Delicias | C3: J-50202212-0 | D3: Maracay | E3: Aragua | G3: La Floresta, Maracay | H3: Las Delicias | J3: 0424-3388016 | K3: Dr. Vidal Ruiz | L3: farmaciallasdelicias@locatel.com | W3: repbiofarco | X3: dispositivosbiofarco@gmail.com
A4: 3 | B4: Farma Salud | C4: 0424-3388016 | D4: Maracay | E4: Aragua | G4: Av. Jose Maria Vargas, La Floresta | H4: La Floresta | J4: 0414-3456070 | K4: Anni Suárez | S4: Alta | V4: 45803 | W4: repbiofarco | X4: dispositivosbiofarco@gmail.com
A5: 4 | B5: Farmacia Farmadía | C5: 0414-3456070 | D5: Maracay | E5: Aragua | G5: El Piñonal, Maracay | H5: El Piñonal | I5: 0414-0471853 | W5: repbiofarco | X5: dispositivosbiofarco@gmail.com
A6: 5 | B6: Farmacia Gran Vía | C6: J-07509720-3 | D6: Maracay | E6: Aragua | G6: 70 Av. Miranda, Maracay 2101, Aragua, Venezuela | H6: El Carmen | I6: 0243-2335512 | J6: 0414-1479994 | K6: Ana Matute | L6: farmaciagranviamcy@gmail.com | O6: TRUE | S6: Baja | V6: 45785 | W6: repbiofarco | X6: dispositivosbiofarco@gmail.com
A7: 6 | B7: Farmacia Lincoln | C7: J-30296726-4 | D7: Maracay | E7: Aragua | G7: Av. Bolívar, Maracay, Aragua, Venezuela | H7: Centro | I7: 0414-5880833 | J7: 0412-398327 | K7: Rubexi Magallanes | O7: TRUE | S7: Media | U7: @farmacialincoln | V7: 45806 | W7: repbiofarco | X7: dispositivosbiofarco@gmail.com
A8: 7 | B8: Farmacia LaFarma C.C. Las Américas | C8: J-31116593-2 | D8: Maracay | E8: Aragua | G8: Avenida Las Delicias, Maracay 2101, Aragua, Venezuela | H8: Las Delicias | I8: 0412-4660774 | J8: 0412-4660774 | K8: Alejandra Franco | O8: TRUE | S8: Media | U8: @lafarmacclasamericas | V8: 45806 | W8: repbiofarco | X8: dispositivosbiofarco@gmail.com
A9: 8 | B9: Farmacia SAAS Av. Los Aviadores | C9: J-50265214-0 | D9: Palo Negro | E9: Aragua | G9: Av. Los Aviadores, Palo Negro, Maracay, Edo. Aragua. | H9: Av. Los Aviadores | I9: 0424-3080504 | J9: 0424-3774424 | K9: Briscarlet Romero | U9: @farmaciasaas_aviadores | W9: repbiofarco | X9: dispositivosbiofarco@gmail.com
A10: 9 | B10: Farmacia El Sol | C10: 0412-1443505 | D10: Maracay | E10: Aragua | G10: Local 1, C.C Hormiga Center, Av Bolivar, Nivel 1 Calle Sanchez Carrero, Maracay 2101, Aragua | H10: C.C. Hormiga Center | I10: 0412-1443505 | J10: 0412-1443505 | K10: Geisy | W10: repbiofarco | X10: dispositivosbiofarco@gmail.com
A11: 10 | B11: Farmacia El Sol II | C11: 0424-3612060 | D11: Maracay | E11: Aragua | G11: Local #58, Av Miranda, 2101 Calle Sanchez Carrero, Maracay 2101, Aragua | H11: Av Miranda | I11: 0424-3612060 | J11: 0424-3612060 | K11: Helecky | W11: repbiofarco | X11: dispositivosbiofarco@gmail.com
A12: 11 | B12: Farmacia SAAS Las Delicias | C12: J-07000750-8 | D12: Maracay | E12: Aragua | G12: 8C6Q+PXF, Av Principal El Castaño, Maracay 2101, Aragua, Venezuela | H12: Delicias | I12: 0424-3823338 | J12: 0424-3053065 | K12: Dulce García | S12: Alta | T12: 0.33333333 | U12: @saasav.lasdelicias | V12: 45824 | W12: repbiofarco | X12: dispositivosbiofarco@gmail.com
A13: 12 | B13: Farma Vital El Limón | C13: 0414-0531788 | D13: Maracay | E13: Aragua | G13: Av. Universidad | H13: El Limón | I13: 0414-0531788 | J13: 0412-4427134 | K13: Jenxy | W13: repbiofarco | X13: dispositivosbiofarco@gmail.com
A14: 13 | B14: Farma Vital Terminal Central | C14: 0414-4751430 | D14: Maracay | E14: Aragua | G14: Terminal de Pasajeros | H14: Terminal | I14: 0414-4751430 | J14: 0424-3448938 | K14: Pedro Bravo | W14: repbiofarco | X14: dispositivosbiofarco@gmail.com
A15: 14 | B15: Farma Vital 19 de Abril | C15: 0412-8948596 | D15: Maracay | E15: Aragua | G15: Diagonal Clinica Lugo, C.C Vista Lago, Avenida 19 de Abril, Maracay 2101, Aragua | H15: 19 de Abril | I15: 0412-8948596 | J15: 0424-3533959 | K15: Dilimary | L15: farmavitalmaracay@gmail.com | W15: repbiofarco | X15: dispositivosbiofarco@gmail.com
A16: 15 | B16: Farma Vital Campo Alegre | C16: J-31072776-7 | D16: Maracay | E16: Aragua | G16: Av. Bermudez, Maracay 2103, Aragua, Venezuela | H16: Sur de Aragua | I16: 0412-4837874 | J16: 0424-3074961 | K16: Kariana Alfonso | O16: TRUE | S16: Media | V16: 45782 | W16: repbiofarco | X16: dispositivosbiofarco@gmail.com
A17: 16 | B17: Distufar Av. Bermudez | C17: 0412-5979880 | E17: Aragua | I17: 0412-5979880 | J17: 0412-5979880 | K17: Andrea Gutierrez | W17: repbiofarco | X17: dispositivosbiofarco@gmail.com
A18: 17 | B18: Distufar Santa Ines | C18: 0412-3982006 | E18: Aragua | I18: 0412-3982006 | J18: 0412-3982006 | K18: Yasmin | W18: repbiofarco | X18: dispositivosbiofarco@gmail.com
A19: 18 | B19: Farmacia La Ganadera | C19: J-4028240-9 | D19: Maracay | E19: Aragua | G19: Av. Constitución, Maracay, Aragua, Venezuela | H19: Santa Rosa | I19: 0414-1518972 | J19: 0414-5340201 | K19: Jose Torres | O19: TRUE | S19: Media | U19: @farmacia_la_ganadera | V19: 45828 | W19: repbiofarco | X19: dispositivosbiofarco@gmail.com
A20: 19 | B20: Farma Milán Santa Rita | C20: 0414-9479464 | E20: Aragua | I20: 0414-9479464 | J20: 0414-9479464 | K20: Deisy Zar | W20: repbiofarco | X20: dispositivosbiofarco@gmail.com
A21: 20 | B21: Farma Milán La Morita | C21: 0414-4636195 | E21: Aragua | I21: 0414-4636195 | J21: 0414-4636195 | K21: Fatima Fernandez | W21: repbiofarco | X21: dispositivosbiofarco@gmail.com
A22: 21 | B22: Farmacia Farma Store | C22: 0414-4907867 | E22: Aragua | I22: 0414-4907867 | J22: 0414-4907867 | K22: Veronica Olmos | W22: repbiofarco | X22: dispositivosbiofarco@gmail.com
A23: 22 | B23: Farmacia Policlínico | C23: 0424-3680773 | E23: Aragua | I23: 0424-3680773 | J23: 0424-3680773 | K23: Carolina | W23: repbiofarco | X23: dispositivosbiofarco@gmail.com
A24: 23 | B24: Farmacia Central 19 | C24: 0412-9932540 | E24: Aragua | I24: 0412-9932540 | J24: 0412-9932540 | K24: Lcdo. Jose Narval | W24: repbiofarco | X24: dispositivosbiofarco@gmail.com
A25: 24 | B25: Farmacia Fartodo Amor, Salud y Vida | C25: 0424-3245936 | E25: Aragua | I25: 0424-3245936 | J25: 0424-3245936 | K25: Jhony | W25: repbiofarco | X25: dispositivosbiofarco@gmail.com
A26: 25 | B26: Farmacia Farma Vista | C26: 0412-8686043 | E26: Aragua | I26: 0412-8686043 | J26: 0412-8686043 | K26: Katy | W26: repbiofarco | X26: dispositivosbiofarco@gmail.com
A27: 26 | B27: Farmacia Farma Health | C27: 0414-4894502 | E27: Aragua | I27: 0414-4894502 | J27: 0414-4894502 | K27: Indira Infante | W27: repbiofarco | X27: dispositivosbiofarco@gmail.com
A28: 27 | B28: Farmacia Social El Gran Descuento | C28: 0414-4344133 | E28: Aragua | I28: 0414-4344133 | J28: 0414-4344133 | K28: Lisbeth Darchart | W28: repbiofarco | X28: dispositivosbiofarco@gmail.com
A29: 28 | B29: Farmacia Las Mercedes | C29: 0414-4749193 | E29: Aragua | I29: 0414-4749193 | J29: 0414-4749193 | K29: Odeisa Olmedo | W29: repbiofarco | X29: dispositivosbiofarco@gmail.com
A30: 29 | B30: Farmacia Bendición Sucre | C30: 0412-8954493 | E30: Aragua | I30: 0412-8954493 | J30: 0412-8954493 | K30: Wilberky | W30: repbiofarco | X30: dispositivosbiofarco@gmail.com
A31: 30 | B31: Farmacia Far Centro | C31: 0414-4430816 | E31: Aragua | I31: 0414-4430816 | J31: 0414-4430816 | K31: Luis | W31: repbiofarco | X31: dispositivosbiofarco@gmail.com
A32: 31 | B32: Farmacia María de San José | C32: 0426-1453117 | E32: Aragua | I32: 0426-1453117 | J32: 0426-1453117 | K32: Yepyiza | W32: repbiofarco | X32: dispositivosbiofarco@gmail.com
A33: 32 | B33: Farmacia Santa Inés | C33: 0424-3482385 | E33: Aragua | I33: 0424-3482385 | J33: 0424-3482385 | W33: repbiofarco | X33: dispositivosbiofarco@gmail.com
A34: 33 | B34: Farmacia Jose Gregorio Hernandez | C34: 0414-5905389 | E34: Aragua | I34: 0414-5905389 | J34: 0414-5905389 | K34: Pablo Segundo | W34: repbiofarco | X34: dispositivosbiofarco@gmail.com
A35: 34 | B35: Farmacia VIP | C35: 0414-4591967 | E35: Aragua | I35: 0414-4591967 | J35: 0414-4591967 | K35: Genesis Mendez | W35: repbiofarco | X35: dispositivosbiofarco@gmail.com
A36: 35 | B36: Farma VIP Administración | C36: 0414-4906644 | E36: Aragua | I36: 0414-4906644 | J36: 0414-4906644 | K36: Aikon | W36: repbiofarco | X36: dispositivosbiofarco@gmail.com
A37: 36 | B37: FarmaBallenas | D37: Maracay | E37: Aragua | G37: IPSFA Av. Bolívar Este, Maracay 2101, Aragua, Venezuela | H37: IPSFA | W37: repbiofarco | X37: dispositivosbiofarco@gmail.com
A38: 37 | B38: Farmacia SAAS San José | D38: Maracay | E38: Aragua | F38: Limonada Laxante , Zincosol , Fleryfol , NeuroVital Kids , Acetafen , Calzinc D , Vitacon C , Emulsión , NeutroX , Leche de Magnesia Original , Leche de Magnesia Menta , Calamina , Citrato de Potasio , Cloruro de Magnesio | G38: C. San José, Esquina Este del IVSS. Maracay 2103, Aragua, Venezuela | H38: IVSS San José | O38: Visita mensual | W38: repbiofarco | X38: dispositivosbiofarco@gmail.com
A39: 38 | B39: Farmacia SAAS Maracay Plaza | C39: 0412-8905442 | D39: Maracay | E39: Aragua | G39: Av Aragua C/ Av Bermudez C.C. Maracay Plaza Nivel PB LOCAL 45C Y | H39: C.C. Maracay Plaza | I39: 0412-8905442 | J39: 0424-3089344 | K39: Emily Nuñez | W39: repbiofarco | X39: dispositivosbiofarco@gmail.com
A40: 39 | B40: Farmatodo Cristal | C40: 0243-2157912 | D40: Maracay | E40: Aragua | G40: Urb San Carlos entre Av Los Samanes y Av. Fuerzas Aereas | H40: Av. Fuerzas Aéreas Sur | I40: 0243-2157912 | S40: Alta | W40: repbiofarco | X40: dispositivosbiofarco@gmail.com
...

Sheet Inventario_Farmacia
A1: ID Inventario | B1: ID_Visita | C1: ID_Farmacia | D1: ID_Producto | E1: Cantidad Existente | F1: Precio Registrado | G1: Fecha Registro | H1: Lote | I1: FechaElaboracion | J1: FechaVencimiento | K1: Notas Inventario | L1: Caras_Exhibicion | M1: Caras_Competencia | N1: Personal_Capacitado | O1: POP_Visible | P1: Alerta_Sustitucion | Q1: Registrado Por | R1: ID_Usuario | S1: SUBMITTED BY
A2: a4d65f49 | D2: PRO-013 | E2: 3 | F2: 790 | G2: 45805.341 | Q2: dispositivosbiofarco@gmail.com | R2: repbiofarco | S2: dispositivosbiofarco@gmail.com
A3: a262dcb8 | C3: ac0b0b41 | D3: PRO-013 | E3: 3 | F3: 790 | G3: 45805.346 | Q3: dispositivosbiofarco@gmail.com | R3: repbiofarco | S3: dispositivosbiofarco@gmail.com
A4: 113f8d32 | C4: ac0b0b41 | D4: PRO-026 | E4: 3 | G4: 45805.349 | Q4: dispositivosbiofarco@gmail.com | R4: repbiofarco | S4: dispositivosbiofarco@gmail.com
A5: 8a55710b | C5: ac0b0b41 | D5: PRO-051 | E5: 2 | G5: 45805.352 | Q5: dispositivosbiofarco@gmail.com | R5: repbiofarco | S5: dispositivosbiofarco@gmail.com
A6: a397dd41 | C6: 2f00830e | D6: PRO-026 | E6: 1 | F6: 6.96 | G6: 45805.362 | Q6: dispositivosbiofarco@gmail.com | R6: repbiofarco | S6: dispositivosbiofarco@gmail.com
A7: 13776726 | C7: 2f00830e | D7: PRO-026 | E7: 2 | F7: 6.96 | G7: 45805.363 | K7: Menta | Q7: dispositivosbiofarco@gmail.com | R7: repbiofarco | S7: dispositivosbiofarco@gmail.com
A8: df38fde4 | C8: 2f00830e | D8: PRO-035 | E8: 1 | F8: 8.35 | G8: 45805.363 | K8: -0.4 | Q8: dispositivosbiofarco@gmail.com | R8: repbiofarco | S8: dispositivosbiofarco@gmail.com
A9: 82b8aa1e | C9: 2f00830e | D9: PRO-051 | E9: 2 | F9: 7.79 | G9: 45805.364 | Q9: dispositivosbiofarco@gmail.com | R9: repbiofarco | S9: dispositivosbiofarco@gmail.com
A10: 0cf4f2f8 | C10: 2f00830e | D10: PRO-015 | E10: 2 | F10: 11.23 | G10: 45805.368 | K10: De litro | Q10: dispositivosbiofarco@gmail.com | R10: repbiofarco | S10: dispositivosbiofarco@gmail.com
A11: c9e9de61 | C11: 2f00830e | D11: PRO-016 | E11: 1 | F11: 9.56 | G11: 45805.368 | K11: Medio en 5.20 | Q11: dispositivosbiofarco@gmail.com | R11: repbiofarco | S11: dispositivosbiofarco@gmail.com
A12: e891a81e | B12: 8fa2efef | D12: PRO-003 | E12: 2 | F12: 2.1 | G12: 45805.733 | Q12: dispositivosbiofarco@gmail.com | R12: repbiofarco | S12: dispositivosbiofarco@gmail.com
A13: bb3c40ee | B13: 43cb1656 | D13: PRO-003 | G13: 45813.317 | Q13: dispositivosbiofarco@gmail.com | R13: repbiofarco | S13: dispositivosbiofarco@gmail.com
A14: 933419ac | B14: 43cb1656 | D14: PRO-011 | G14: 45813.317 | Q14: dispositivosbiofarco@gmail.com | R14: repbiofarco | S14: dispositivosbiofarco@gmail.com
A15: dafd27fc | B15: 43cb1656 | D15: PRO-040 | G15: 45813.317 | Q15: dispositivosbiofarco@gmail.com | R15: repbiofarco | S15: dispositivosbiofarco@gmail.com
A16: 653c9ad7 | B16: b681a6af | D16: PRO-028 | E16: 1 | G16: 45813.318 | Q16: dispositivosbiofarco@gmail.com | R16: repbiofarco | S16: dispositivosbiofarco@gmail.com
A17: b392778c | C17: 46 | D17: PRO-035 | E17: 5 | F17: 1346.45 | G17: 45813.341 | Q17: dispositivosbiofarco@gmail.com | R17: repbiofarco | S17: dispositivosbiofarco@gmail.com
A18: 0dbfa633 | C18: 46 | D18: PRO-026 | E18: 8 | F18: 992.1 | G18: 45813.342 | K18: Sabor Natural | Q18: dispositivosbiofarco@gmail.com | R18: repbiofarco | S18: dispositivosbiofarco@gmail.com
A19: b91d6ec8 | C19: 46 | D19: PRO-026 | E19: 5 | F19: 992.1 | G19: 45813.342 | K19: Sabor Menta | Q19: dispositivosbiofarco@gmail.com | R19: repbiofarco | S19: dispositivosbiofarco@gmail.com
A20: fabc7cf9 | C20: 46 | D20: PRO-051 | E20: 1 | F20: 893.2 | G20: 45813.343 | Q20: dispositivosbiofarco@gmail.com | R20: repbiofarco | S20: dispositivosbiofarco@gmail.com
A21: de67ef3f | C21: 46 | D21: PRO-013 | E21: 5 | F21: 1119.7 | G21: 45813.343 | Q21: dispositivosbiofarco@gmail.com | R21: repbiofarco | S21: dispositivosbiofarco@gmail.com
A22: ecf50d22 | C22: 97 | D22: PRO-035 | E22: 3 | F22: 1023.1 | G22: 45813.344 | Q22: dispositivosbiofarco@gmail.com | R22: repbiofarco | S22: dispositivosbiofarco@gmail.com
A23: e5f9a180 | C23: 97 | D23: PRO-026 | E23: 8 | F23: 795.3 | G23: 45813.345 | K23: Sabor Natural | Q23: dispositivosbiofarco@gmail.com | R23: repbiofarco | S23: dispositivosbiofarco@gmail.com
A24: 8e6d7917 | C24: 97 | D24: PRO-026 | E24: 5 | F24: 795.3 | G24: 45813.345 | K24: Sabor Menta | Q24: dispositivosbiofarco@gmail.com | R24: repbiofarco | S24: dispositivosbiofarco@gmail.com
A25: 02de536b | C25: 97 | D25: PRO-051 | E25: 2 | F25: 685.3 | G25: 45813.346 | Q25: dispositivosbiofarco@gmail.com | R25: repbiofarco | S25: dispositivosbiofarco@gmail.com
A26: 98f20f1a | C26: 97 | D26: PRO-013 | E26: 4 | F26: 850.75 | G26: 45813.347 | Q26: dispositivosbiofarco@gmail.com | R26: repbiofarco | S26: dispositivosbiofarco@gmail.com
A27: dd91df1e | C27: 99 | D27: PRO-035 | E27: 3 | F27: 1023.1 | G27: 45813.347 | Q27: dispositivosbiofarco@gmail.com | R27: repbiofarco | S27: dispositivosbiofarco@gmail.com
A28: 848b5ab6 | C28: 99 | D28: PRO-026 | E28: 8 | F28: 795.3 | G28: 45813.347 | K28: Sabor Natural | Q28: dispositivosbiofarco@gmail.com | R28: repbiofarco | S28: dispositivosbiofarco@gmail.com
A29: c8271adf | C29: 99 | D29: PRO-026 | E29: 5 | F29: 795.3 | G29: 45813.348 | K29: Sabor a Menta | Q29: dispositivosbiofarco@gmail.com | R29: repbiofarco | S29: dispositivosbiofarco@gmail.com
A30: 706a3886 | C30: 99 | D30: PRO-051 | E30: 2 | F30: 685.75 | G30: 45813.394 | Q30: dispositivosbiofarco@gmail.com | R30: repbiofarco | S30: dispositivosbiofarco@gmail.com
A31: bd837d50 | C31: 99 | D31: PRO-013 | E31: 3 | F31: 850.75 | G31: 45813.395 | Q31: dispositivosbiofarco@gmail.com | R31: repbiofarco | S31: dispositivosbiofarco@gmail.com
A32: b371085e | C32: 100 | D32: PRO-035 | E32: 5 | F32: 1023.1 | G32: 45813.395 | Q32: dispositivosbiofarco@gmail.com | R32: repbiofarco | S32: dispositivosbiofarco@gmail.com
A33: 59f006af | C33: 100 | D33: PRO-026 | E33: 7 | F33: 795.3 | G33: 45813.396 | Q33: dispositivosbiofarco@gmail.com | R33: repbiofarco | S33: dispositivosbiofarco@gmail.com
A34: 4c72097a | C34: 100 | D34: PRO-026 | E34: 4 | F34: 795.3 | G34: 45813.396 | Q34: dispositivosbiofarco@gmail.com | R34: repbiofarco | S34: dispositivosbiofarco@gmail.com
A35: e49178d5 | C35: 100 | D35: PRO-013 | E35: 4 | F35: 850.75 | G35: 45813.396 | Q35: dispositivosbiofarco@gmail.com | R35: repbiofarco | S35: dispositivosbiofarco@gmail.com
A36: 92be3b8e | C36: 101 | D36: PRO-035 | E36: 4 | F36: 1023.1 | G36: 45813.397 | Q36: dispositivosbiofarco@gmail.com | R36: repbiofarco | S36: dispositivosbiofarco@gmail.com
A37: f8ee0ba0 | C37: 101 | D37: PRO-026 | E37: 7 | F37: 795.3 | G37: 45813.397 | Q37: dispositivosbiofarco@gmail.com | R37: repbiofarco | S37: dispositivosbiofarco@gmail.com
A38: 97cce3cd | C38: 101 | D38: PRO-026 | E38: 4 | F38: 793.3 | G38: 45813.397 | K38: Sabor Menta | Q38: dispositivosbiofarco@gmail.com | R38: repbiofarco | S38: dispositivosbiofarco@gmail.com
A39: 651bc22c | C39: 101 | D39: PRO-051 | E39: 1 | F39: 685.3 | G39: 45813.397 | Q39: dispositivosbiofarco@gmail.com | R39: repbiofarco | S39: dispositivosbiofarco@gmail.com
A40: b9ea7047 | C40: 101 | D40: PRO-013 | E40: 3 | F40: 850.5 | G40: 45813.398 | Q40: dispositivosbiofarco@gmail.com | R40: repbiofarco | S40: dispositivosbiofarco@gmail.com
...

Sheet FiltrosRotacion
A1: ID_Filtro | B1: FarmaciaSeleccionada | C1: ProductoSeleccionado | D1: ID_Usuario | E1: SUBMITTED BY
A2: 1 | B2: 22 | C2: PRO-035 | D2: repbiofarco | E2: dispositivosbiofarco@gmail.com

Sheet Transferencias
A1: ID_Pedido | B1: Fecha | C1: ID_Cotizacion | D1: ID_Farmacia | E1: ID_Drogueria | F1: Estado | G1: Prioridad | H1: Notas | I1: Contador | J1: Reporte Transferencia | K1: ID_Usuario | L1: SUBMITTED BY
A2: e05a8a92 | B2: 45882 | D2: 18ea49b4 | E2: 1 | F2: Procesado | G2: Media | H2: Código Nena C686 | I2: 2 | J2: /Transferencias/Farmacial Real 2022-1.pdf | K2: repbiofarco | L2: dispositivosbiofarco@gmail.com
A3: 3425186a | B3: 45890 | D3: 964789a9 | E3: 1 | F3: Procesado | G3: Alta | H3: Codigo Nena D-006 | I3: 2 | J3: /Transferencias/Farmacia Far Todo Virgen del Valle-1.pdf | K3: repbiofarco | L3: dispositivosbiofarco@gmail.com
A4: 8ab9ba93 | B4: 45903 | D4: 137cdbda | E4: 1 | F4: Procesado | G4: Media | H4: Codigo Nena 6050 | I4: 1 | J4: /Transferencias/Farmacia La Barraca-1.pdf | K4: repbiofarco | L4: dispositivosbiofarco@gmail.com
A5: 80f366fc | B5: 45911 | D5: 4fde48bf | E5: 1 | F5: Procesado | G5: Alta | H5: DRONENA Codigo 7633, COBECA Codigo R28711 o DrovenCentro Codigo 600010. | I5: 1 | J5: /Transferencias/Farmacia Malanga-1.pdf | K5: repbiofarco | L5: dispositivosbiofarco@gmail.com
A6: e3a5eaff | B6: 45911 | D6: 708d54e0 | E6: 3 | F6: Procesado | G6: Media | H6: COBECA Codigo: 31560 | I6: 1 | J6: /Transferencias/Farmacia Mi Esperanza 2424-1.pdf | K6: repbiofarco | L6: dispositivosbiofarco@gmail.com
A7: fa842f90 | B7: 45911 | D7: 69b36f13 | E7: 3 | F7: Procesado | G7: Alta | H7: Código COBECA 28929 | I7: 1 | J7: /Transferencias/Farmasol Boulevard 2020-1.pdf | K7: repbiofarco | L7: dispositivosbiofarco@gmail.com
A8: 361fbffa | B8: 45922 | D8: c32e41f5 | E8: 6 | F8: Procesado | G8: Media | H8: Codigo CrisMedical FAR-03502 | I8: 1 | J8: /Transferencias/Farmacia FARMALEON-1.pdf | K8: repbiofarco | L8: dispositivosbiofarco@gmail.com
A9: c1598867 | B9: 45923 | D9: 5 | E9: 3 | F9: Procesado | G9: Media | H9: Codigo COBECA 26352 | I9: 1 | J9: /Transferencias/Farma Shop Solidaria Ayacucho-1.pdf | K9: repbiofarco | L9: dispositivosbiofarco@gmail.com
A10: 695f9aeb | B10: 45939 | D10: b7417481 | E10: 3 | F10: Procesado | G10: Media | H10: Codigo COBECA 31445 | I10: 2 | J10: /Transferencias/FarmaJumbo Turmero-1.pdf | K10: repbiofarco | L10: dispositivosbiofarco@gmail.com
A11: 007d6a2f | B11: 45979 | C11: 7582d0b8 | D11: 48e9fe71 | E11: 2 | F11: Procesado | G11: Media | H11: Codigo VitalClinic 1296 | I11: 2 | J11: /Transferencias/Farmacia Grupo Medical Casa Salud-1.pdf | K11: repbiofarco | L11: dispositivosbiofarco@gmail.com
A12: 3f29acaa | B12: 45932 | D12: 52 | E12: 1 | F12: Procesado | G12: Media | H12: Codigo Nena $132 | I12: 2 | J12: /Transferencias/Farmacia El Sol-1.pdf | K12: repbiofarco | L12: dispositivosbiofarco@gmail.com
A13: 80a01443 | B13: 45939 | D13: 0be7a231 | E13: 1 | F13: Procesado | G13: Media | H13: Codigo Nena C836 - Codigo COBECA 50538 o 30538 | I13: 1 | J13: /Transferencias/Eurofarmacia-.pdf | K13: repbiofarco | L13: dispositivosbiofarco@gmail.com
A14: 334faf19 | B14: 45951 | D14: 708d54e0 | E14: 2 | F14: Procesado | G14: Media | H14: Codigo VitalClinic 4393 ó COBECA 31560 | I14: 1 | J14: /Transferencias/Farmacia Mi Esperanza 2424-.pdf | K14: repbiofarco | L14: dispositivosbiofarco@gmail.com
A15: ee689f4a | B15: 45951 | D15: 69b36f13 | E15: 3 | F15: Procesado | G15: Alta | H15: Código COBECA 28929 | I15: 1 | J15: /Transferencias/Farmasol Boulevard 2020-.pdf | K15: repbiofarco | L15: dispositivosbiofarco@gmail.com
A16: 835aaea4 | B16: 45951 | D16: 67a0121b | E16: 1 | F16: Pendiente | G16: Alta | H16: Código Nena E542 | J16: /Transferencias/FarmaSol Santos Michelena II-.pdf | K16: repbiofarco | L16: dispositivosbiofarco@gmail.com
A17: 0f72910e | B17: 45951 | D17: cfaf6844 | E17: 1 | F17: Pendiente | G17: Alta | H17: Código Nena D635 | J17: /Transferencias/Farmasol Vargas-.pdf | K17: repbiofarco | L17: dispositivosbiofarco@gmail.com
A18: a40cde83 | B18: 45966 | C18: 465ce288 | D18: 2cb82336 | E18: 4 | F18: Procesado | G18: Media | H18: Código Drovencentro 600445 - Código Insuaminca 03345 | I18: 1 | J18: /Transferencias/Mc Time Farmacia-.pdf | K18: repbiofarco | L18: dispositivosbiofarco@gmail.com
A20: 846f7f35 | B20: 46147 | C20: ddb3bd3c | D20: 0b9ea836 | E20: 061dbd84 | F20: Aprobada | G20: Alta | H20: Gentionar inventario con fecha de vencimiento 2028 | J20: /Files/Stock_Reports/Harissa Droguería, C.A._0b9ea836.pdf | K20: repbiofarco | L20: dispositivosbiofarco@gmail.com

Sheet Productos_X_Transferencia
A1: ID_Detalle | B1: ID_Transferencia | C1: ID_Producto | D1: Cantidad | E1: Nota | F1: ID_Drogueria_Temp | G1: ID_Usuario | H1: SUBMITTED BY
A2: 9a652359 | B2: e05a8a92 | C2: f39ad541 | D2: 2 | G2: repbiofarco | H2: dispositivosbiofarco@gmail.com
A3: 60dba42a | B3: e05a8a92 | C3: 5676e0c6 | D3: 2 | G3: repbiofarco | H3: dispositivosbiofarco@gmail.com
A4: 6d590629 | B4: e05a8a92 | C4: 1f610f8d | D4: 2 | G4: repbiofarco | H4: dispositivosbiofarco@gmail.com
A5: 82768ca3 | B5: 3425186a | C5: PRO-005 | D5: 8 | G5: repbiofarco | H5: dispositivosbiofarco@gmail.com
A6: 14e74be3 | B6: 3425186a | C6: PRO-002 | D6: 6 | G6: repbiofarco | H6: dispositivosbiofarco@gmail.com
A7: 9fb8bd30 | B7: 3425186a | C7: PRO-007 | D7: 12 | G7: repbiofarco | H7: dispositivosbiofarco@gmail.com
A8: a558af8f | B8: 3425186a | C8: PRO-007 | D8: 6 | G8: repbiofarco | H8: dispositivosbiofarco@gmail.com
A9: deea8eac | B9: 3425186a | C9: PRO-008 | D9: 4 | G9: repbiofarco | H9: dispositivosbiofarco@gmail.com
A10: b112573e | B10: 3425186a | C10: PRO-028 | D10: 6 | G10: repbiofarco | H10: dispositivosbiofarco@gmail.com
A11: cb8b4aff | B11: 3425186a | C11: PRO-028 | D11: 6 | G11: repbiofarco | H11: dispositivosbiofarco@gmail.com
A12: c372de24 | B12: 3425186a | C12: PRO-015 | D12: 6 | G12: repbiofarco | H12: dispositivosbiofarco@gmail.com
A13: def9f42e | B13: 3425186a | C13: 51243510 | D13: 6 | G13: repbiofarco | H13: dispositivosbiofarco@gmail.com
... A24: 5d24747b | B24: 80f366fc | C24: PRO-017 | D24: 2 | G24: repbiofarco | H24: dispositivosbiofarco@gmail.com
A25: 1adb23a0 | B25: 80f366fc | C25: PRO-007 | D25: 3 | E25: 60 ml | G25: repbiofarco | H25: dispositivosbiofarco@gmail.com
A26: 498287b2 | B26: 80f366fc | C26: PRO-007 | D26: 3 | E26: 240 ml | G26: repbiofarco | H26: dispositivosbiofarco@gmail.com
A27: 986bc3ac | B27: 80f366fc | C27: PRO-053 | D27: 3 | E27: 120 ml | G27: repbiofarco | H27: dispositivosbiofarco@gmail.com
A28: 51194f44 | B28: 80f366fc | C28: PRO-008 | D28: 3 | E28: 120 ml | G28: repbiofarco | H28: dispositivosbiofarco@gmail.com
A29: 431eaa79 | B29: 80f366fc | C29: PRO-008 | D29: 3 | E29: 60 ml | G29: repbiofarco | H29: dispositivosbiofarco@gmail.com
A30: 9d2479df | B30: 80f366fc | C30: PRO-023 | D30: 1 | G30: repbiofarco | H30: dispositivosbiofarco@gmail.com
A31: fa343e8f | B31: 80f366fc | C31: PRO-013 | D31: 1 | G31: repbiofarco | H31: dispositivosbiofarco@gmail.com
A32: 3a07b176 | B32: 80f366fc | C32: PRO-016 | D32: 1 | E32: 500 ml | G32: repbiofarco | H32: dispositivosbiofarco@gmail.com
A33: 19551857 | B33: 80f366fc | C33: PRO-016 | D33: 1 | E33: 1000 ml | G33: repbiofarco | H33: dispositivosbiofarco@gmail.com
A34: 874a95a7 | B34: 80f366fc | C34: 51243510 | D34: 1 | G34: repbiofarco | H34: dispositivosbiofarco@gmail.com
A35: 8e3c773b | B35: 80f366fc | C35: PRO-021 | D35: 2 | G35: repbiofarco | H35: dispositivosbiofarco@gmail.com
A36: aae70791 | B36: 80f366fc | C36: f39ad541 | D36: 1 | E36: Coco | G36: repbiofarco | H36: dispositivosbiofarco@gmail.com
A37: 48fe5fee | B37: 80f366fc | C37: 5676e0c6 | D37: 1 | E37: Fresa | G37: repbiofarco | H37: dispositivosbiofarco@gmail.com
A38: f697d3e5 | B38: 80f366fc | C38: 1f610f8d | D38: 1 | E38: Uva | G38: repbiofarco | H38: dispositivosbiofarco@gmail.com
A39: 047c486f | B39: 80f366fc | C39: PRO-024 | D39: 3 | G39: repbiofarco | H39: dispositivosbiofarco@gmail.com
A40: 794754ec | B40: 80f366fc | C40: PRO-063 | D40: 1 | G40: repbiofarco | H40: dispositivosbiofarco@gmail.com
A41: 4e3f97ed | B41: 80f366fc | C41: PRO-027 | D41: 1 | G41: repbiofarco | H41: dispositivosbiofarco@gmail.com
A42: c051264d | B42: 80f366fc | C42: PRO-072 | D42: 1 | G42: repbiofarco | H42: dispositivosbiofarco@gmail.com
A43: a7994610 | B43: 80f366fc | C43: PRO-029 | D43: 1 | E43: Uguento | G43: repbiofarco | H43: dispositivosbiofarco@gmail.com
A44: 7a17cbb8 | B44: 80f366fc | C44: PRO-031 | D44: 1 | E44: Roll-on | G44: repbiofarco | H44: dispositivosbiofarco@gmail.com
A45: 77d98f0b | B45: 80f366fc | C45: PRO-030 | E45: Spray | G45: repbiofarco | H45: dispositivosbiofarco@gmail.com
A46: 4c1b7fd5 | B46: 80f366fc | C46: PRO-033 | D46: 1 | G46: repbiofarco | H46: dispositivosbiofarco@gmail.com
A47: 93ce2540 | B47: 80f366fc | C47: PRO-064 | D47: 2 | G47: repbiofarco | H47: dispositivosbiofarco@gmail.com
A48: dab961a3 | B48: 80f366fc | C48: PRO-034 | D48: 2 | G48: repbiofarco | H48: dispositivosbiofarco@gmail.com
A49: df94128f | B49: 80f366fc | C49: 71df8880269341fce19e2043 | D49: 1 | G49: repbiofarco | H49: dispositivosbiofarco@gmail.com
A50: 25a38fa1 | B50: 80f366fc | C50: eeac8176 | D50: 1 | G50: repbiofarco | H50: dispositivosbiofarco@gmail.com
...

Sheet Cotizaciones
A1: ID_Cotizacion | B1: ID_Visita | C1: ID_Fichero | D1: ID_Farmacia | E1: ID_Drogueria | F1: CondicionCiclo | G1: FechaCreacion | H1: Prioridad | I1: Estado | J1: Archivo | K1: ID_Usuario | L1: SUBMITTED BY
A2: 465ce288 | B2: 58806e4b | D2: 2cb82336 | E2: 4 | G2: 45966 | H2: Media | I2: Aprobada | J2: 1 | K2: repbiofarco | L2: dispositivosbiofarco@gmail.com
A3: 7582d0b8 | B3: 858a5b55 | D3: 48e9fe71 | E3: 2 | G3: 45980 | H3: Media | I3: Aprobada | K3: repbiofarco | L3: dispositivosbiofarco@gmail.com
A4: 57484c41 | B4: bc287360 | D4: f470f649 | E4: 1 | G4: 45982 | H4: Media | I4: Aprobada | J4: 1 | K4: repbiofarco | L4: dispositivosbiofarco@gmail.com
A5: ddb3bd3c | B5: aaa533ec | D5: 0b9ea836 | E5: 061dbd84 | G5: 46148 | H5: Alta | I5: Aprobada | K5: repbiofarco | L5: dispositivosbiofarco@gmail.com

Sheet Productos_X_Cotizacion
A1: ID_Detalle_Cot | B1: ID_Cotizacion | C1: ID_Producto | D1: CantidadSolicitada | E1: PrecioUnitario | F1: Nota | G1: ID_Usuario | H1: SUBMITTED BY
A2: 42bea2b5 | B2: 1d6ae722 | C2: PRO-001 | D2: 2 | G2: repbiofarco | H2: dispositivosbiofarco@gmail.com
A3: 2d459ff2 | B3: 1d6ae722 | C3: PRO-006 | D3: 2 | G3: repbiofarco | H3: dispositivosbiofarco@gmail.com
A4: 1e5c27d8 | B4: 7195c106 | C4: PRO-017 | D4: 2 | G4: repbiofarco | H4: dispositivosbiofarco@gmail.com
A5: 49fa7c8d | B5: 7195c106 | C5: PRO-002 | D5: 5 | G5: repbiofarco | H5: dispositivosbiofarco@gmail.com
A6: 58f9665d | B6: 465ce288 | C6: PRO-013 | D6: 2 | G6: repbiofarco | H6: dispositivosbiofarco@gmail.com
A7: ce8cbb76 | B7: 465ce288 | C7: PRO-033 | D7: 5 | G7: repbiofarco | H7: dispositivosbiofarco@gmail.com
A8: 0036abf3 | B8: 465ce288 | C8: PRO-057 | D8: 6 | F8: Sabor Original | G8: repbiofarco | H8: dispositivosbiofarco@gmail.com
A9: 9ef828a7 | B9: 465ce288 | C9: PRO-050 | D9: 2 | G9: repbiofarco | H9: dispositivosbiofarco@gmail.com
A10: 3f95f2f5 | B10: 465ce288 | C10: PRO-034 | D10: 1 | G10: repbiofarco | H10: dispositivosbiofarco@gmail.com
A11: 6ebf3dce | B11: 57484c41 | C11: PRO-033 | D11: 3 | E11: 479.39 | G11: repbiofarco | H11: dispositivosbiofarco@gmail.com
A12: 9c0046d2 | B12: 57484c41 | C12: PRO-059 | D12: 2 | E12: 5568.42 | G12: repbiofarco | H12: dispositivosbiofarco@gmail.com
A13: df8643e3 | B13: 57484c41 | C13: f39ad541 | D13: 1 | E13: 786.18 | G13: repbiofarco | H13: dispositivosbiofarco@gmail.com
A14: 0dbc1045 | B14: 57484c41 | C14: 5676e0c6 | D14: 1 | E14: 786.18 | G14: repbiofarco | H14: dispositivosbiofarco@gmail.com
A15: 75dcfa0b | B15: 57484c41 | C15: 1f610f8d | D15: 1 | E15: 786.18 | G15: repbiofarco | H15: dispositivosbiofarco@gmail.com
A16: a8f3a790 | B16: 57484c41 | C16: eeac8176 | D16: 1 | E16: 1603.72 | G16: repbiofarco | H16: dispositivosbiofarco@gmail.com
A17: 94c7d409 | B17: 57484c41 | C17: 71df8880269341fce19e2043 | D17: 1 | E17: 1725.75 | G17: repbiofarco | H17: dispositivosbiofarco@gmail.com
A18: c695f7e4 | B18: ddb3bd3c | C18: PRO-026 | D18: 96 | E18: 4.4 | F18: 8% Descuento | G18: repbiofarco | H18: dispositivosbiofarco@gmail.com
A19: 8cc89ee9 | B19: ddb3bd3c | C19: PRO-026-1 | D19: 96 | E19: 4.4 | F19: 8% Descuento | G19: repbiofarco | H19: dispositivosbiofarco@gmail.com
A20: 5a436531 | B20: ddb3bd3c | C20: PRO-035 | D20: 24 | E20: 6 | F20: 7% Descuento | G20: repbiofarco | H20: dispositivosbiofarco@gmail.com
A21: 2a2eb983 | B21: ddb3bd3c | C21: PRO-015 | D21: 60 | E21: 7.5 | F21: 7% Descuento | G21: repbiofarco | H21: dispositivosbiofarco@gmail.com
A22: 1ddb7cf3 | B22: ddb3bd3c | C22: PRO-015-1 | D22: 24 | E22: 5.4 | F22: 8% Descuento | G22: repbiofarco | H22: dispositivosbiofarco@gmail.com
A23: d63fe6c2 | B23: ddb3bd3c | C23: PRO-052 | D23: 60 | E23: 2.3 | F23: 6% Descuento | G23: repbiofarco | H23: dispositivosbiofarco@gmail.com
A24: 4d01dbe5 | B24: ddb3bd3c | C24: PRO-006 | D24: 60 | E24: 2.9 | F24: 6% Descuento | G24: repbiofarco | H24: dispositivosbiofarco@gmail.com
A25: 6bb9b43d | B25: ddb3bd3c | C25: PRO-003 | D25: 60 | E25: 1.1 | F25: 6% Descuento | G25: repbiofarco | H25: dispositivosbiofarco@gmail.com
A26: 1b755bae | B26: ddb3bd3c | C26: PRO-009 | D26: 60 | E26: 0.9 | F26: 6% Descuento | G26: repbiofarco | H26: dispositivosbiofarco@gmail.com
A27: 26780a80 | B27: ddb3bd3c | C27: PRO-011 | D27: 48 | E27: 0.9 | F27: 6% Descuento | G27: repbiofarco | H27: dispositivosbiofarco@gmail.com
A28: 73daaec5 | B28: ddb3bd3c | C28: PRO-010 | D28: 48 | E28: 1.6 | F28: 6% Descuento | G28: repbiofarco | H28: dispositivosbiofarco@gmail.com
A29: 381a9317 | B29: ddb3bd3c | C29: PRO-059 | D29: 48 | E29: 1.9 | F29: 6% Descuento | G29: repbiofarco | H29: dispositivosbiofarco@gmail.com
... A32: 8285ca11 | B32: ddb3bd3c | C32: PRO-043 | D32: 24 | E32: 2.3 | F32: 6% Descuento | G32: repbiofarco | H32: dispositivosbiofarco@gmail.com

Sheet Productos del Pedido
A1: ID_Producto_Pedido | B1: ID_Farmacia | C1: ID_Pedido | D1: Producto | E1: Cantidad | F1: ID_Usuario | G1: SUBMITTED BY
A2: bee24f4a | B2: f470f649 | D2: 3366acf8 | E2: 1 | F2: repbiofarco | G2: dispositivosbiofarco@gmail.com
A3: 581028a9 | B3: f470f649 | D3: a13eb6b6 | E3: 1 | F3: repbiofarco | G3: dispositivosbiofarco@gmail.com
A4: 5b0a3114 | B4: f470f649 | D4: 4f550f56 | E4: 1 | F4: repbiofarco | G4: dispositivosbiofarco@gmail.com
A5: f756aed9 | B5: f470f649 | D5: eeac8176 | E5: 2 | F5: repbiofarco | G5: dispositivosbiofarco@gmail.com
A6: d482b40a | B6: f470f649 | D6: PRO-007 | E6: 2 | F6: repbiofarco | G6: dispositivosbiofarco@gmail.com
A7: 6908964b | B7: f470f649 | D7: PRO-032 | E7: 2 | F7: repbiofarco | G7: dispositivosbiofarco@gmail.com
A8: 3a013bd2 | B8: f470f649 | D8: PRO-032 | E8: 2 | F8: repbiofarco | G8: dispositivosbiofarco@gmail.com

Sheet Drogueria
A1: ID_Drogueria | B1: NombreDrogueria | C1: Codigo_Drogueria | D1: Contacto | E1: Telefono | F1: ID_Usuario | G1: SUBMITTED BY
A2: 1 | B2: DroNena | F2: repbiofarco | G2: dispositivosbiofarco@gmail.com
A3: 2 | B3: VitalClinic | F3: repbiofarco | G3: dispositivosbiofarco@gmail.com
A4: 3 | B4: COBECA | F4: repbiofarco | G4: dispositivosbiofarco@gmail.com
A5: 4 | B5: DrovenCentro | F5: repbiofarco | G5: dispositivosbiofarco@gmail.com
A6: 5 | B6: Dromega | F6: repbiofarco | G6: dispositivosbiofarco@gmail.com
A7: 6 | B7: Crismedical | F7: repbiofarco | G7: dispositivosbiofarco@gmail.com
A8: 7 | B8: VIOVAC | F8: repbiofarco | G8: dispositivosbiofarco@gmail.com
A9: 8 | B9: Insuaminca | F9: repbiofarco | G9: dispositivosbiofarco@gmail.com
A10: 9c0db263 | B10: Bsm Medical | F10: repbiofarco | G10: dispositivosbiofarco@gmail.com
A11: 78a5496c | B11: Zaki Pharma | F11: repbiofarco | G11: dispositivosbiofarco@gmail.com
A12: 65f15348 | B12: Insuaminca | F12: repbiofarco | G12: dispositivosbiofarco@gmail.com
A13: 061dbd83 | B13: DrovenCentro | F13: repbiofarco | G13: dispositivosbiofarco@gmail.com
A14: 061dbd84 | B14: BIOFARCO | F14: repbiofarco | G14: dispositivosbiofarco@gmail.com

Sheet Drogueria_Inventario
A1: ID_Inventario | B1: ID_Drogueria | C1: Codigo_Barras | D1: ID_Producto | E1: CantidadDisponible | F1: Precio | G1: FechaActualizacion | H1: ID_Usuario | I1: SUBMITTED BY
A2: 1 | B2: 1 | C2: 1759161600039 | D2: {=IFERROR(XLOOKUP(TRIM(C2&""), TRIM(Productos!B:B), Productos!A:A), XLOOKUP(TRIM(RIGHT(C2, LEN(C2)-1)&""), TRIM(Productos!B:B), Productos!A:A, " "))} -> PRO-004 | E2: 8 | F2: 26.247937 | G2: 46111 | H2: repbiofarco | I2: dispositivosbiofarco@gmail.com
A3: 2 | B3: 1 | C3: 7591616002272 | D3: {=IFERROR(XLOOKUP(TRIM(C3&""), TRIM(Productos!B:B), Productos!A:A), XLOOKUP(TRIM(RIGHT(C3, LEN(C3)-1)&""), TRIM(Productos!B:B), Productos!A:A, " "))} -> PRO-017 | E3: 23 | F3: 5.2296211 | G3: 46111 | H3: repbiofarco | I3: dispositivosbiofarco@gmail.com
A4: 3 | B4: 1 | C4: 7591616000056 | D4: {=IFERROR(XLOOKUP(TRIM(C4&""), TRIM(Productos!B:B), Productos!A:A), XLOOKUP(TRIM(RIGHT(C4, LEN(C4)-1)&""), TRIM(Productos!B:B), Productos!A:A, " "))} -> PRO-052 | E4: 72 | F4: 3.1238105 | G4: 46111 | H4: repbiofarco | I4: dispositivosbiofarco@gmail.com
A5: 4 | B5: 1 | C5: 7591616000162 | D5: {=IFERROR(XLOOKUP(TRIM(C5&""), TRIM(Productos!B:B), Productos!A:A), XLOOKUP(TRIM(RIGHT(C5, LEN(C5)-1)&""), TRIM(Productos!B:B), Productos!A:A, " "))} -> PRO-005 | E5: 164 | F5: 2.1058316 | G5: 46111 | H5: repbiofarco | I5: dispositivosbiofarco@gmail.com
A6: 5 | B6: 1 | C6: 17591616000138 | D6: {=IFERROR(XLOOKUP(TRIM(C6&""), TRIM(Productos!B:B), Productos!A:A), XLOOKUP(TRIM(RIGHT(C6, LEN(C6)-1)&""), TRIM(Productos!B:B), Productos!A:A, " "))} -> PRO-006 | E6: 23 | F6: 46.906968 | G6: 46111 | H6: repbiofarco | I6: dispositivosbiofarco@gmail.com
A7: 6 | B7: 1 | C7: 7591616002142 | D7: {=IFERROR(XLOOKUP(TRIM(C7&""), TRIM(Productos!B:B), Productos!A:A), XLOOKUP(TRIM(RIGHT(C7, LEN(C7)-1)&""), TRIM(Productos!B:B), Productos!A:A, " "))} -> PRO-002 | E7: 19 | F7: 3.1238105 | G7: 46111 | H7: repbiofarco | I7: dispositivosbiofarco@gmail.com
A8: 7 | B8: 1 | C8: 17591616001463 | D8: {=IFERROR(XLOOKUP(TRIM(C8&""), TRIM(Productos!B:B), Productos!A:A), XLOOKUP(TRIM(RIGHT(C8, LEN(C8)-1)&""), TRIM(Productos!B:B), Productos!A:A, " "))} -> PRO-003 | E8: 41 | F8: 17.325642 | G8: 46111 | H8: repbiofarco | I8: dispositivosbiofarco@gmail.com
A9: 8 | B9: 1 | C9: 7591616000285 | D9: {=IFERROR(XLOOKUP(TRIM(C9&""), TRIM(Productos!B:B), Productos!A:A), XLOOKUP(TRIM(RIGHT(C9, LEN(C9)-1)&""), TRIM(Productos!B:B), Productos!A:A, " "))} -> PRO-007 | E9: 96 | F9: 4.6208421 | G9: 46111 | H9: repbiofarco | I9: dispositivosbiofarco@gmail.com
A10: 9 | B10: 1 | C10: 7591616000315 | D10: {=IFERROR(XLOOKUP(TRIM(C10&""), TRIM(Productos!B:B), Productos!A:A), XLOOKUP(TRIM(RIGHT(C10, LEN(C10)-1)&""), TRIM(Productos!B:B), Productos!A:A, " "))} -> PRO-007-1 | E10: 402 | F10: 2.1058316 | G10: 46111 | H10: repbiofarco | I10: dispositivosbiofarco@gmail.com
A11: 10 | B11: 1 | C11: 7591616000261 | D11: {=IFERROR(XLOOKUP(TRIM(C11&""), TRIM(Productos!B:B), Productos!A:A), XLOOKUP(TRIM(RIGHT(C11, LEN(C11)-1)&""), TRIM(Productos!B:B), Productos!A:A, " "))} -> PRO-007-2 | E11: 138 | F11: 2.9441684 | G11: 46111 | H11: repbiofarco | I11: dispositivosbiofarco@gmail.com
A12: 11 | B12: 1 | C12: 7591616002111 | D12: {=IFERROR(XLOOKUP(TRIM(C12&""), TRIM(Productos!B:B), Productos!A:A), XLOOKUP(TRIM(RIGHT(C12, LEN(C12)-1)&""), TRIM(Productos!B:B), Productos!A:A, " "))} -> PRO-053 | E12: 60 | F12: 2.4651158 | G12: 46111 | H12: repbiofarco | I12: dispositivosbiofarco@gmail.com
A13: 12 | B13: 1 | C13: 17591616000343 | D13: {=IFERROR(XLOOKUP(TRIM(C13&""), TRIM(Productos!B:B), Productos!A:A), XLOOKUP(TRIM(RIGHT(C13, LEN(C13)-1)&""), TRIM(Productos!B:B), Productos!A:A, " "))} -> PRO-008 | E13: 0 | F13: 2.7463158 | G13: 46041 | H13: repbiofarco | I13: dispositivosbiofarco@gmail.com
... A131: 130 | B131: 3 | C131: 7599558000042 | D131: {=IFERROR(XLOOKUP(TRIM(C131&""), TRIM(Productos!B:B), Productos!A:A), XLOOKUP(TRIM(RIGHT(C131, LEN(C131)-1)&""), TRIM(Productos!B:B), Productos!A:A, " "))} -> PRO-065-1 | E131: 9 | F131: 14.86 | G131: 46119 | H131: repbiofarco | I131: dispositivosbiofarco@gmail.com
A132: 131 | B132: 061dbd83 | C132: 7591616000032 | D132: {=IFERROR(XLOOKUP(TRIM(C132&""), TRIM(Productos!B:B), Productos!A:A), XLOOKUP(TRIM(RIGHT(C132, LEN(C132)-1)&""), TRIM(Productos!B:B), Productos!A:A, " "))} | E132: 12 | F132: 2.19 | G132: 46119 | H132: repbiofarco | I132: dispositivosbiofarco@gmail.com
A133: 132 | B133: 061dbd83 | C133: 7591616000162 | D133: {=IFERROR(XLOOKUP(TRIM(C133&""), TRIM(Productos!B:B), Productos!A:A), XLOOKUP(TRIM(RIGHT(C133, LEN(C133)-1)&""), TRIM(Productos!B:B), Productos!A:A, " "))} -> PRO-005 | E133: 222 | F133: 2.11 | G133: 46119 | H133: repbiofarco | I133: dispositivosbiofarco@gmail.com
A134: 133 | B134: 061dbd83 | C134: 7591616001466 | D134: {=IFERROR(XLOOKUP(TRIM(C134&""), TRIM(Productos!B:B), Productos!A:A), XLOOKUP(TRIM(RIGHT(C134, LEN(C134)-1)&""), TRIM(Productos!B:B), Productos!A:A, " "))} | E134: 9 | F134: 1.43 | G134: 46119 | H134: repbiofarco | I134: dispositivosbiofarco@gmail.com
A135: 134 | B135: 061dbd83 | C135: 7591616000285 | D135: {=IFERROR(XLOOKUP(TRIM(C135&""), TRIM(Productos!B:B), Productos!A:A), XLOOKUP(TRIM(RIGHT(C135, LEN(C135)-1)&""), TRIM(Productos!B:B), Productos!A:A, " "))} -> PRO-007 | E135: 61 | F135: 4.64 | G135: 46119 | H135: repbiofarco | I135: dispositivosbiofarco@gmail.com
A136: 135 | B136: 061dbd83 | C136: 7591616002111 | D136: {=IFERROR(XLOOKUP(TRIM(C136&""), TRIM(Productos!B:B), Productos!A:A), XLOOKUP(TRIM(RIGHT(C136, LEN(C136)-1)&""), TRIM(Productos!B:B), Productos!A:A, " "))} -> PRO-053 | E136: 12 | F136: 2.44 | G136: 46119 | H136: repbiofarco | I136: dispositivosbiofarco@gmail.com
A137: 136 | B137: 061dbd83 | C137: 7591616000346 | D137: {=IFERROR(XLOOKUP(TRIM(C137&""), TRIM(Productos!B:B), Productos!A:A), XLOOKUP(TRIM(RIGHT(C137, LEN(C137)-1)&""), TRIM(Productos!B:B), Productos!A:A, " "))} | E137: 30 | F137: 3.54 | G137: 46119 | H137: repbiofarco | I137: dispositivosbiofarco@gmail.com
A138: 137 | B138: 061dbd83 | C138: 7591616001480 | D138: {=IFERROR(XLOOKUP(TRIM(C138&""), TRIM(Productos!B:B), Productos!A:A), XLOOKUP(TRIM(RIGHT(C138, LEN(C138)-1)&""), TRIM(Productos!B:B), Productos!A:A, " "))} | E138: 14 | F138: 1.26 | G138: 46119 | H138: repbiofarco | I138: dispositivosbiofarco@gmail.com
A139: 138 | B139: 061dbd83 | C139: 7591616001510 | D139: {=IFERROR(XLOOKUP(TRIM(C139&""), TRIM(Productos!B:B), Productos!A:A), XLOOKUP(TRIM(RIGHT(C139, LEN(C139)-1)&""), TRIM(Productos!B:B), Productos!A:A, " "))} | E139: 51 | F139: 1.18 | G139: 46119 | H139: repbiofarco | I139: dispositivosbiofarco@gmail.com
A140: 139 | B140: 061dbd83 | C140: 7591616000360 | D140: {=IFERROR(XLOOKUP(TRIM(C140&""), TRIM(Productos!B:B), Productos!A:A), XLOOKUP(TRIM(RIGHT(C140, LEN(C140)-1)&""), TRIM(Productos!B:B), Productos!A:A, " "))} -> PRO-010 | E140: 5 | F140: 1.6 | G140: 46119 | H140: repbiofarco | I140: dispositivosbiofarco@gmail.com
A141: 140 | B141: 061dbd83 | C141: 7591616002227 | D141: {=IFERROR(XLOOKUP(TRIM(C141&""), TRIM(Productos!B:B), Productos!A:A), XLOOKUP(TRIM(RIGHT(C141, LEN(C141)-1)&""), TRIM(Productos!B:B), Productos!A:A, " "))} -> PRO-028 | E141: 39 | F141: 4.89 | G141: 46119 | H141: repbiofarco | I141: dispositivosbiofarco@gmail.com
